Workbook

Sheet 00_README
A1: IP MASTER DATASET 2021–2025 – TRƯỜNG ĐẠI HỌC THÀNH ĐÔ
A3: Mục | B3: Nội dung
A4: Mục đích | B4: Khung dữ liệu phục vụ đề tài cấp cơ sở: kiểm kê kết quả KHCN → nhận diện TSTT → xác lập/bảo hộ → ứng dụng/chuyển giao → giá trị.
A5: Trạng thái | B5: Bản v0.7: hoàn thiện blueprint Chương 2, kế hoạch bảng/biểu đồ và bản nháp các mục 2.1–2.4. Cấu trúc Chương 2 đi theo logic: thể chế → năng lực tạo đầu ra/TSTT → portfolio quyền → quy trình nhận diện/bảo hộ → ứng dụng/khai thác → case tracing → gap → đánh giá chung.
A6: Nguyên tắc đơn vị phân tích | B6: PROJECT = 1 đề tài; OUTPUT = 1 đầu ra; IP_ASSET = 1 TSTT hoặc cụm TSTT; PROTECTION = 1 hồ sơ/quyền; UTILIZATION_VALUE = 1 lần/hình thức khai thác.
A7: Không đồng nhất | B7: Không coi số văn bằng bảo hộ là tổng số TSTT. TSTT tiềm năng được nhận diện trước, sau đó mới xét hình thức quyền phù hợp.
A8: Mã thiếu dữ liệu | B8: Để trống = chưa có bằng chứng; 'Chưa xác minh' = có dấu hiệu nhưng chưa đủ hồ sơ; không suy diễn từ tên đề tài.
A9: Nguồn chính | B9: Tổng hợp đề tài KHCN cấp cơ sở của GV 2021–2025; Quy chế hoạt động KHCN 2021; Quy chế quản trị TSTT; các bảng công bố/sách/giáo trình.
A10: Chiến lược | B10: Mã Strategic Cluster theo 4 trụ cột: Smart Mobility, Digital Services, Global Communication, Wellness & Care; có thể dùng 'Khác/Chưa phân loại'.
A11: Khuyến nghị sử dụng | B11: Hoàn thiện dữ liệu thô trước khi tính tỷ lệ và kết luận. Mọi chỉ số KPI hiện tại chỉ phản ánh các dòng mẫu đã nhập.
A12: Phiên bản | B12: v0.7 – Chapter 2 writing blueprint + table/figure plan + draft sections 2.1–2.4.
A14: v0.8 (Claude, 16/9/2026) | B14: Dọn trùng lặp thế hệ bảng, chuẩn hóa từ điển loại đầu ra, tách mẫu số, thêm KPI bằng công thức và 8 phép kiểm tra tự động. Chi tiết ở 00_CHANGELOG_v08. Sheet có tiền tố ZZ_CU_ là bản cũ, không dùng để trích dẫn.

Sheet 00_CHANGELOG_v08
A1: NHẬT KÝ THAY ĐỔI – TỪ v0.7 SANG v0.8
A2: Không xóa dữ liệu gốc. Mọi thay đổi đều cộng thêm hoặc đổi tên, có thể lần ngược.
A4: STT | B4: Vấn đề ở v0.7 | C4: Xử lý ở v0.8 | D4: Sheet liên quan
A5: 1 | B5: Hai thế hệ bảng cùng tồn tại: 01_PROJECT 7 dòng và 01_PROJECT_ALL 38 dòng; 02_OUTPUT 19 dòng và 02_OUTPUT_ALL 90 dòng; 03_IP_ASSET 7 dòng; 08_KPI_DASHBOARD. Nguy cơ trích nhầm số. | C5: Đổi tên thành ZZ_CU_… và dồn xuống cuối file. Dữ liệu vẫn giữ nguyên để đối chiếu, nhưng không dùng để trích dẫn. | D5: ZZ_CU_01_PROJECT; ZZ_CU_02_OUTPUT; ZZ_CU_03_IP_ASSET; ZZ_CU_08_KPI_DASHBOARD
A6: 2 | B6: 02_OUTPUT dùng mã Output cũ dạng O2022-37-01, khác mã hiện hành O-2022-37-01. Ghép nhầm là chắc chắn nếu dùng lẫn. | C6: Ghi nhận xung đột mã; bảng cũ chỉ để tham chiếu lịch sử. Mã chính thức là mã của 02_OUTPUT_ALL. | D6: ZZ_CU_02_OUTPUT
A7: 3 | B7: 04_PROTECTION và 05_UTIL_VALUE trống, mỗi sheet 1000 dòng ràng buộc nhập liệu, nhưng đã bị 13B_PROTECTION_FULL thay thế. | C7: Đổi tên thành TPL_… để chỉ rõ đây là biểu mẫu thu thập dữ liệu về sau, không phải dữ liệu thực. | D7: TPL_04_PROTECTION; TPL_05_UTIL_VALUE
A8: 4 | B8: Từ điển loại đầu ra bị vỡ: 09_LOOKUPS có 11 giá trị, dữ liệu dùng 14 giá trị, 9 giá trị nằm ngoài từ điển; 'Sản phẩm/prototype' và 'Mô hình/prototype' trùng nghĩa. | C8: Lập bảng ánh xạ 14 giá trị gốc sang 8 nhóm chuẩn. Giữ nguyên cột gốc, thêm cột P và Q tính bằng VLOOKUP nên sửa từ điển là dữ liệu tự cập nhật. | D8: 09B_MAP_LOAI_DAURA; 02_OUTPUT_ALL cột P, Q
A9: 5 | B9: 34/90 dòng đầu ra là báo cáo tổng kết — sản phẩm hành chính bắt buộc. Để trong mẫu số làm loãng mọi tỷ lệ chuyển hóa. | C9: Thêm cột Nhóm mẫu số với 4 giá trị: Bắt buộc hành chính, Công bố, Ứng viên TSTT, Khác/quản trị. Mọi tỷ lệ ở 08B đều loại nhóm bắt buộc khỏi mẫu số. | D9: 02_OUTPUT_ALL cột Q; 08B_KPI_v08
A10: 6 | B10: 08_KPI_ALL gõ tay toàn bộ giá trị, tỷ lệ để dạng 0,4736 và không ghi mẫu số. | C10: Lập 08B_KPI_v08 tính bằng công thức, mỗi chỉ số có cột tử số, mẫu số và ghi chú diễn giải. Ô tỷ lệ ở 08_KPI_ALL được định dạng lại thành phần trăm. | D10: 08B_KPI_v08
A11: 7 | B11: Không có cơ chế phát hiện lỗi khi dữ liệu được bổ sung. | C11: Lập 8 phép kiểm tra tự động: trùng mã, khóa mồ côi, giá trị ngoài từ điển, tổng nhóm mẫu số. Mọi dòng phải trả về OK. | D11: 24_QC_CHECKS
A12: 8 | B12: Portfolio SHTT mới dựa vào danh sách nội bộ, chưa đối chiếu nguồn độc lập. | C12: Chưa xử lý ở v0.8. Đề nghị tra ngược 9 đối tượng đã có số trên cơ sở dữ liệu công khai của Cục Sở hữu trí tuệ, ghi kết quả vào 13B thành cột xác minh độc lập. | D12: 13B_PROTECTION_FULL
A13: 9 | B13: File chứa tên cá nhân, tên doanh nghiệp đối tác, số văn bằng, kèm nhận định về việc thiếu hồ sơ. | C13: Chưa xử lý ở v0.8. Trước khi đưa vào luận án hoặc báo cáo, cân nhắc mã hóa tên cá nhân và tên doanh nghiệp. | D13: Toàn file

Sheet 01_PROJECT_ALL
A1: Project_ID | B1: Năm giao/nhóm | C1: Mã đề tài | D1: Tên đề tài | E1: Cấp | F1: Chủ nhiệm | G1: Đơn vị chủ trì | H1: Nhóm ngành chuẩn hóa | I1: Strategic_Cluster | J1: Ngày nghiệm thu | K1: Xếp loại | L1: Kinh phí_VND | M1: Hình thức kinh phí | N1: Số người tham gia | O1: Đầu ra ứng dụng ghi trong hồ sơ? | P1: Số đầu ra (formula) | Q1: Nguồn | R1: Ghi chú xác minh
A2: P2021-20 | B2: 2021 | C2: 20-2021/KHCN | D2: Nghiên cứu năng lực nghe hiểu của sinh viên cử nhân thực hành tiếng Nhật năm thứ 2 tại Trường Đại học Thành Đô | E2: Cơ sở | F2: Lê Thanh Phương | G2: Khoa DL-NN | H2: Ngôn ngữ/Giáo dục | I2: Global Communication | J2: 44816 | K2: Đạt | M2: Quy đổi giờ NCKH | N2: 1 | O2: Không ghi nhận | P2: =COUNTIF(02_OUTPUT_ALL!$B:$B,A2) -> 1 | Q2: Tổng hợp đề tài KHCN cấp cơ sở của GV 2021-2025.pdf, tr.1 | R2: Năm nhóm theo mục NĂM 2021; nghiệm thu năm 2022.
A3: P2021-22 | B3: 2021 | C3: 22-2021/KHCN | D3: Đánh giá giáo trình Network dùng cho sinh viên năm thứ nhất Trường Đại học Thành Đô | E3: Cơ sở | F3: Nguyễn Thị Vân Anh | G3: Khoa DL-NN | H3: Ngôn ngữ/Giáo dục | I3: Global Communication | J3: 44816 | K3: Đạt | M3: Quy đổi giờ NCKH | N3: 1 | O3: Không ghi nhận | P3: =COUNTIF(02_OUTPUT_ALL!$B:$B,A3) -> 1 | Q3: Tổng hợp đề tài KHCN cấp cơ sở của GV 2021-2025.pdf, tr.1
A4: P2021-24 | B4: 2021 | C4: 24-2021/KHCN | D4: Đánh giá ứng dụng mô hình học tập kết hợp (Blended Learning) trong việc dạy và học tiếng Anh tại Trường Đại học Thành Đô | E4: Cơ sở | F4: Đinh Thị Thanh Huyền | G4: Khoa DL-NN | H4: Ngôn ngữ/Giáo dục | I4: Global Communication | J4: 44816 | K4: Tốt | M4: Quy đổi giờ NCKH | N4: 1 | O4: Không ghi nhận | P4: =COUNTIF(02_OUTPUT_ALL!$B:$B,A4) -> 1 | Q4: Tổng hợp đề tài KHCN cấp cơ sở của GV 2021-2025.pdf, tr.1
A5: P2021-27 | B5: 2021 | C5: 27-2021/KHCN | D5: Thực trạng và động lực phát triển chuyên môn của giáo viên | E5: Cơ sở | F5: Phan Thị Thanh Thảo | G5: Khoa DL-NN | H5: Khoa học giáo dục | I5: Khác/Chưa phân loại | J5: 44370 | K5: Đạt | M5: Quy đổi giờ NCKH | N5: 6 | O5: Không ghi nhận | P5: =COUNTIF(02_OUTPUT_ALL!$B:$B,A5) -> 3 | Q5: Tổng hợp đề tài KHCN cấp cơ sở của GV 2021-2025.pdf, tr.1
A6: P2021-28 | B6: 2021 | C6: 28-2021/KHCN | D6: Hoạt động công bố quốc tế tại Việt Nam: Thực trạng và ý nghĩa đối với cộng đồng và những nhà hoạch định chính sách | E6: Cơ sở | F6: Phan Thị Thanh Thảo | G6: Khoa DL-NN | H6: Khoa học giáo dục/Chính sách KHCN | I6: Khác/Chưa phân loại | J6: 44370 | K6: Đạt | M6: Quy đổi giờ NCKH | N6: 8 | O6: Không ghi nhận | P6: =COUNTIF(02_OUTPUT_ALL!$B:$B,A6) -> 3 | Q6: Tổng hợp đề tài KHCN cấp cơ sở của GV 2021-2025.pdf, tr.2
A7: P2021-37 | B7: 2021 | C7: 37-2021/KHCN | D7: Rào cản của các doanh nghiệp vừa và nhỏ trong việc áp dụng thương mại điện tử tại Việt Nam | E7: Cơ sở | F7: Nguyễn Thị Hay | G7: Khoa KT | H7: Kinh tế/Thương mại điện tử | I7: Digital Services | J7: 44536 | K7: Đạt | M7: Quy đổi giờ NCKH | N7: 2 | O7: Không ghi nhận | P7: =COUNTIF(02_OUTPUT_ALL!$B:$B,A7) -> 2 | Q7: Tổng hợp đề tài KHCN cấp cơ sở của GV 2021-2025.pdf, tr.2
A8: P2022-01 | B8: 2022 | C8: 01-2022/KHCN | D8: Đề án thành lập Tạp chí Nghiên cứu khoa học và phát triển thuộc Trường Đại học Thành Đô | E8: Cơ sở | F8: Vũ Thị Thanh Minh | G8: Phòng KHCN | H8: Quản lý KHCN/Xuất bản khoa học | I8: Khác/Chưa phân loại | J8: 44613 | K8: Tốt | M8: Quy đổi giờ NCKH | N8: 5 | O8: Có | P8: =COUNTIF(02_OUTPUT_ALL!$B:$B,A8) -> 1 | Q8: Tổng hợp đề tài KHCN cấp cơ sở của GV 2021-2025.pdf, tr.2 | R8: Sản phẩm là Tạp chí Nghiên cứu khoa học và phát triển.
A9: P2022-02 | B9: 2022 | C9: 02-2022/KHCN | D9: Nghiên cứu xây dựng Quy chế tuyển sinh và đào tạo trình độ thạc sỹ theo Thông tư số 23/2021/TT-BGDĐT của Bộ Giáo dục và Đào tạo tại Trường Đại học Thành Đô | E9: Cơ sở | F9: Trần Hữu Dào | G9: Khoa SĐH | H9: Quản trị giáo dục/Pháp quy nội bộ | I9: Khác/Chưa phân loại | J9: 44627 | K9: Đạt | M9: Quy đổi giờ NCKH | N9: 1 | O9: Có | P9: =COUNTIF(02_OUTPUT_ALL!$B:$B,A9) -> 1 | Q9: Tổng hợp đề tài KHCN cấp cơ sở của GV 2021-2025.pdf, tr.2 | R9: Sản phẩm là Quy chế tuyển sinh và đào tạo trình độ thạc sĩ.
A10: P2022-12 | B10: 2022 | C10: 12-2022/KHCN | D10: Nâng cao khả năng được tuyển dụng của sinh viên ngành tiếng Anh Khoa Du lịch - Ngoại ngữ qua kỳ thực tập doanh nghiệp | E10: Cơ sở | F10: Đinh Thị Thanh Huyền | G10: Khoa DL-NN | H10: Ngôn ngữ/Đào tạo gắn doanh nghiệp | I10: Global Communication | J10: 44872 | K10: Tốt | M10: Quy đổi giờ NCKH | N10: 1 | O10: Không ghi nhận | P10: =COUNTIF(02_OUTPUT_ALL!$B:$B,A10) -> 1 | Q10: Tổng hợp đề tài KHCN cấp cơ sở của GV 2021-2025.pdf, tr.2
A11: P2022-13 | B11: 2022 | C11: 13-2022/KHCN | D11: Đánh giá giáo trình "New English file" dành cho học viên cao học tại Trường Đại học Thành Đô | E11: Cơ sở | F11: Phan Thị Thanh Thảo | G11: Khoa DL-NN | H11: Ngôn ngữ/Giáo dục | I11: Global Communication | J11: 44872 | K11: Tốt | M11: Quy đổi giờ NCKH | N11: 2 | O11: Không ghi nhận | P11: =COUNTIF(02_OUTPUT_ALL!$B:$B,A11) -> 1 | Q11: Tổng hợp đề tài KHCN cấp cơ sở của GV 2021-2025.pdf, tr.3
A12: P2022-14 | B12: 2022 | C12: 14-2022/KHCN | D12: A study on job satisfaction among teachers at TDU (Đánh giá sự hài lòng của giảng viên tại Đại học Thành Đô) | E12: Cơ sở | F12: Nguyễn Thị Vân Anh | G12: Khoa DL-NN | H12: Khoa học giáo dục/Nhân sự | I12: Khác/Chưa phân loại | J12: 44872 | K12: Tốt | M12: Quy đổi giờ NCKH | N12: 1 | O12: Không ghi nhận | P12: =COUNTIF(02_OUTPUT_ALL!$B:$B,A12) -> 1 | Q12: Tổng hợp đề tài KHCN cấp cơ sở của GV 2021-2025.pdf, tr.3
A13: P2022-15 | B13: 2022 | C13: 15-2022/KHCN | D13: Nghiên cứu ảnh hưởng của hình thức dạy học trực tuyến đến kết quả học tập của sinh viên Khoa Du lịch - Ngoại ngữ, Trường Đại học Thành Đô | E13: Cơ sở | F13: Phan Thị Phương Thảo | G13: Khoa DL-NN | H13: Khoa học giáo dục | I13: Global Communication | J13: 44873 | K13: Tốt | M13: Quy đổi giờ NCKH | N13: 1 | O13: Không ghi nhận | P13: =COUNTIF(02_OUTPUT_ALL!$B:$B,A13) -> 1 | Q13: Tổng hợp đề tài KHCN cấp cơ sở của GV 2021-2025.pdf, tr.3
A14: P2022-37 | B14: 2022 | C14: 37-2022/KHCN | D14: Tính toán thiết kế panel kiểm tra và sửa chữa hệ thống khởi động điện trên ô tô | E14: Cơ sở | F14: Phạm Viết Xuân | G14: Khoa CNKT Ô tô | H14: Kỹ thuật ô tô | I14: Smart Mobility | J14: 44874 | K14: Đạt | L14: 5000000 | M14: Tiền mặt | N14: 1 | O14: Có | P14: =COUNTIF(02_OUTPUT_ALL!$B:$B,A14) -> 2 | Q14: Tổng hợp đề tài KHCN cấp cơ sở của GV 2021-2025.pdf, tr.3
A15: P2022-39 | B15: 2022 | C15: 39-2022/KHCN | D15: Nghiên cứu chế tạo vật liệu cầm máu trên cơ sở chitosan và cao nhọ nồi | E15: Cơ sở | F15: Nguyễn Ngọc Linh | G15: Khoa Dược | H15: Dược/Vật liệu y sinh | I15: Wellness & Care | J15: 44875 | K15: Đạt | L15: 29000000 | M15: Tiền mặt | N15: 5 | O15: Có | P15: =COUNTIF(02_OUTPUT_ALL!$B:$B,A15) -> 2 | Q15: Tổng hợp đề tài KHCN cấp cơ sở của GV 2021-2025.pdf, tr.3
A16: P2022-40 | B16: 2022 | C16: 40-2022/KHCN | D16: Nghiên cứu xây dựng bộ mẫu dược liệu áp dụng giảng dạy tại Trường Đại học Thành Đô | E16: Cơ sở | F16: Lê Văn Tuyến | G16: Khoa Dược | H16: Dược/Giáo dục dược | I16: Wellness & Care | J16: 44875 | K16: Đạt | L16: 50000000 | M16: Tiền mặt | N16: 7 | O16: Có | P16: =COUNTIF(02_OUTPUT_ALL!$B:$B,A16) -> 2 | Q16: Tổng hợp đề tài KHCN cấp cơ sở của GV 2021-2025.pdf, tr.3
A17: P2022-51 | B17: 2022 | C17: 51-2022/KHCN | D17: Quản lý hoạt động huy động vốn của các công ty chứng khoán tại Việt Nam: Thực trạng và một số kiến nghị | E17: Cơ sở | F17: Đinh Thị Phi Nga | G17: Khoa Kinh tế | H17: Tài chính/Chứng khoán | I17: Digital Services | J17: 44876 | K17: Đạt | M17: Quy đổi giờ NCKH | N17: 2 | O17: Không ghi nhận | P17: =COUNTIF(02_OUTPUT_ALL!$B:$B,A17) -> 2 | Q17: Tổng hợp đề tài KHCN cấp cơ sở của GV 2021-2025.pdf, tr.4
A18: P2023-01 | B18: 2023 | C18: 01-2023/KHCN | D18: Bồi dưỡng phương pháp tư duy biện chứng Hồ Chí Minh cho sinh viên Trường Đại học Thành Đô hiện nay | E18: Cơ sở | F18: Ngô Nhị Ngọc Linh | G18: Khoa KHCB | H18: Lý luận chính trị/Giáo dục | I18: Khác/Chưa phân loại | J18: 45246 | K18: Khá | L18: 3000000 | M18: Tiền mặt | N18: 2 | O18: Có | P18: =COUNTIF(02_OUTPUT_ALL!$B:$B,A18) -> 3 | Q18: Tổng hợp đề tài KHCN cấp cơ sở của GV 2021-2025.pdf, tr.4 | R18: Có mô tả ứng dụng tại Trường.
A19: P2023-02 | B19: 2023 | C19: 02-2023/KHCN | D19: Tiếp cận CDIO để nâng cao chất lượng dạy học học phần thực hành hướng dẫn du lịch tại Trường Đại học Thành Đô | E19: Cơ sở | F19: Nguyễn Thị Bích | G19: Khoa DL-NN | H19: Du lịch/Giáo dục | I19: Global Communication | J19: 45253 | K19: Tốt | L19: 5000000 | M19: Tiền mặt | N19: 2 | O19: Có | P19: =COUNTIF(02_OUTPUT_ALL!$B:$B,A19) -> 3 | Q19: Tổng hợp đề tài KHCN cấp cơ sở của GV 2021-2025.pdf, tr.4 | R19: Có mô tả ứng dụng tại Trường.
A20: P2023-03 | B20: 2023 | C20: 03-2023/KHCN | D20: Sử dụng phương pháp học tập dự án để thúc đẩy sự tự chủ của sinh viên trong học phần cú pháp học | E20: Cơ sở | F20: Phan Thị Thanh Thảo | G20: Khoa DL-NN | H20: Ngôn ngữ/Giáo dục | I20: Global Communication | J20: 45257 | K20: Tốt | L20: 3000000 | M20: Tiền mặt | N20: 3 | O20: Có | P20: =COUNTIF(02_OUTPUT_ALL!$B:$B,A20) -> 3 | Q20: Tổng hợp đề tài KHCN cấp cơ sở của GV 2021-2025.pdf, tr.5 | R20: Hồ sơ ghi bài báo ISSN nhưng chú thích '(ko có bài báo)'.
A21: P2023-04 | B21: 2023 | C21: 04-2023/KHCN | D21: Flipped classroom in higher education: Students' perspective | E21: Cơ sở | F21: Nguyễn Thị Vân Anh | G21: Khoa DL-NN | H21: Khoa học giáo dục | I21: Global Communication | J21: 45257 | K21: Đạt | L21: 3000000 | M21: Tiền mặt | N21: 3 | O21: Có | P21: =COUNTIF(02_OUTPUT_ALL!$B:$B,A21) -> 3 | Q21: Tổng hợp đề tài KHCN cấp cơ sở của GV 2021-2025.pdf, tr.5 | R21: Hồ sơ ghi bài báo ISSN nhưng chú thích '(ko có bài báo)'.
A22: P2023-05 | B22: 2023 | C22: 05-2023/KHCN | D22: Chính sách khuyến khích cho các công bố khoa học tại một số trường đại học ngoài công lập ở Việt Nam | E22: Cơ sở | F22: Nguyễn Thị Hảo | G22: Khoa Điện, Điện tử | H22: Chính sách KHCN/Quản trị đại học | I22: Khác/Chưa phân loại | J22: 45246 | K22: Tốt | L22: 5000000 | M22: Tiền mặt | N22: 4 | O22: Có | P22: =COUNTIF(02_OUTPUT_ALL!$B:$B,A22) -> 3 | Q22: Tổng hợp đề tài KHCN cấp cơ sở của GV 2021-2025.pdf, tr.6 | R22: Ứng dụng làm tài liệu tham khảo xây dựng chính sách/quy chế KHCN.
A23: P2023-07 | B23: 2023 | C23: 07-2023/KHCN | D23: Nâng cao nhận thức về luật hình sự Việt Nam cho sinh viên Trường Đại học Thành Đô | E23: Cơ sở | F23: Vũ Thị Thu Hà | G23: Khoa Kinh tế - Luật | H23: Luật/Giáo dục pháp luật | I23: Khác/Chưa phân loại | J23: 45254 | K23: Đạt | L23: 1000000 | M23: Tiền mặt | N23: 2 | O23: Có | P23: =COUNTIF(02_OUTPUT_ALL!$B:$B,A23) -> 3 | Q23: Tổng hợp đề tài KHCN cấp cơ sở của GV 2021-2025.pdf, tr.6 | R23: Hồ sơ ghi bài báo ISSN nhưng chú thích '(ko có bài báo)'.
A24: P2023-08 | B24: 2023 | C24: 08-2023/KHCN | D24: Ứng dụng mô hình hợp tác giáo dục giữa Nhà trường - Doanh nghiệp trong nghiên cứu chiết xuất tinh dầu từ vỏ bưởi | E24: Cơ sở | F24: Phan Thị Thanh Thảo | G24: Viện REK | H24: Dược/Hợp tác ĐH-DN | I24: Wellness & Care | J24: 45243 | K24: Tốt | L24: 50000000 | M24: Tiền mặt | N24: 8 | O24: Có | P24: =COUNTIF(02_OUTPUT_ALL!$B:$B,A24) -> 3 | Q24: Tổng hợp đề tài KHCN cấp cơ sở của GV 2021-2025.pdf, tr.7 | R24: Sản phẩm ghi chuyển giao cho Trường để thương mại hóa.
A25: P2024-06 | B25: 2024 | C25: 06-2024/KHCN | D25: Nghiên cứu ứng dụng quy trình sản xuất xà phòng tảo biển hữu cơ | E25: Cơ sở | F25: Nguyễn Ngọc Linh | G25: Khoa Dược | H25: Dược/Mỹ phẩm | I25: Wellness & Care | J25: 45611 | K25: Tốt | L25: 58000000 | M25: Tiền mặt | N25: 4 | O25: Có | P25: =COUNTIF(02_OUTPUT_ALL!$B:$B,A25) -> 4 | Q25: Tổng hợp đề tài KHCN cấp cơ sở của GV 2021-2025.pdf, tr.7
A26: P2024-07 | B26: 2024 | C26: 07-2024/KHCN | D26: Nghiên cứu xây dựng bộ tiêu bản hiển vi cố định trong giảng dạy học phần Ký sinh trùng tại Trường Đại học Thành Đô | E26: Cơ sở | F26: Phạm Thị Bích Đào | G26: Khoa Dược | H26: Dược/Ký sinh trùng/Giáo dục | I26: Wellness & Care | J26: 45611 | K26: Tốt | L26: 43000000 | M26: Tiền mặt | N26: 2 | O26: Có | P26: =COUNTIF(02_OUTPUT_ALL!$B:$B,A26) -> 4 | Q26: Tổng hợp đề tài KHCN cấp cơ sở của GV 2021-2025.pdf, tr.7
A27: P2024-08 | B27: 2024 | C27: 08-2024/KHCN | D27: Cải tiến quy trình chiết xuất Rutin từ hoa Hòe (Sophora japonica L.) trong giảng dạy tại Trường Đại học Thành Đô | E27: Cơ sở | F27: Vũ Quốc Mạnh | G27: Khoa Dược | H27: Dược/Chiết xuất dược liệu | I27: Wellness & Care | J27: 45611 | K27: Tốt | L27: 13250000 | M27: Tiền mặt | N27: 2 | O27: Có | P27: =COUNTIF(02_OUTPUT_ALL!$B:$B,A27) -> 5 | Q27: Tổng hợp đề tài KHCN cấp cơ sở của GV 2021-2025.pdf, tr.8
A28: P2024-09 | B28: 2024 | C28: 09-2024/KHCN | D28: Nghiên cứu bào chế sản phẩm hỗ trợ giảm cân theo y học cổ truyền | E28: Cơ sở | F28: Nguyễn Đăng Việt | G28: Khoa Dược | H28: Dược/Bào chế | I28: Wellness & Care | J28: 45611 | K28: Đạt | L28: 8500000 | M28: Tiền mặt | N28: 3 | O28: Có | P28: =COUNTIF(02_OUTPUT_ALL!$B:$B,A28) -> 4 | Q28: Tổng hợp đề tài KHCN cấp cơ sở của GV 2021-2025.pdf, tr.8
A29: P2024-10 | B29: 2024 | C29: 10-2024/KHCN | D29: Triết lý nhân sinh trong thơ văn của Nguyễn Đình Chiểu và vận dụng giáo dục đạo đức cho sinh viên Trường Đại học Thành Đô hiện nay | E29: Cơ sở | F29: Ngô Nhị Ngọc Linh | G29: Khoa KHCB | H29: Nhân văn/Giáo dục | I29: Khác/Chưa phân loại | J29: 45597 | K29: Đạt | L29: 3000000 | M29: Tiền mặt | N29: 3 | O29: Không ghi nhận | P29: =COUNTIF(02_OUTPUT_ALL!$B:$B,A29) -> 2 | Q29: Tổng hợp đề tài KHCN cấp cơ sở của GV 2021-2025.pdf, tr.8
A30: P2024-12 | B30: 2024 | C30: 12-2024/KHCN | D30: Tích hợp giáo dục vì sự phát triển bền vững trong dạy học “sinh thái học và môi trường” (Sinh học 12) | E30: Cơ sở | F30: Hà Văn Dũng | G30: Viện ReK | H30: Khoa học giáo dục/Phát triển bền vững | I30: Khác/Chưa phân loại | J30: 45594 | K30: Đạt | M30: Tự tìm nhà tài trợ | N30: 5 | O30: Không ghi nhận | P30: =COUNTIF(02_OUTPUT_ALL!$B:$B,A30) -> 3 | Q30: Tổng hợp đề tài KHCN cấp cơ sở của GV 2021-2025.pdf, tr.9
A31: P2024-13 | B31: 2024 | C31: 13-2024/KHCN | D31: Quan điểm của Francis Fukuyama về sự cáo chung của lịch sử trong tác phẩm Sự cáo chung của lịch sử và Con người cuối cùng | E31: Cơ sở | F31: Ngô Nhị Ngọc Linh | G31: Khoa KHCB | H31: Triết học/Nhân văn | I31: Khác/Chưa phân loại | J31: 45597 | K31: Đạt | M31: Tự tìm nhà tài trợ | N31: 3 | O31: Không ghi nhận | P31: =COUNTIF(02_OUTPUT_ALL!$B:$B,A31) -> 2 | Q31: Tổng hợp đề tài KHCN cấp cơ sở của GV 2021-2025.pdf, tr.9
A32: P2024-14 | B32: 2024 | C32: 14-2024/KHCN | D32: Rèn luyện năng lực dạy học tích hợp giáo dục vì sự phát triển bền vững cho sinh viên ngành sư phạm sinh học | E32: Cơ sở | F32: Hà Văn Dũng | G32: Viện ReK | H32: Khoa học giáo dục/Phát triển bền vững | I32: Khác/Chưa phân loại | J32: 45785 | K32: Đạt | L32: 19500000 | M32: Tự tìm nguồn tài trợ | N32: 5 | O32: Không ghi nhận | P32: =COUNTIF(02_OUTPUT_ALL!$B:$B,A32) -> 3 | Q32: Tổng hợp đề tài KHCN cấp cơ sở của GV 2021-2025.pdf, phần chuyển tiếp 2024-2025 | R32: Nghiệm thu năm 2025.
A33: P2025-01 | B33: 2025 | C33: 01-2025/KHCN | D33: Sử dụng chiến lược scaffolding để tăng cường sự tham gia của sinh viên trong lớp học tiếng Anh đa trình độ | E33: Cơ sở | F33: Phan Thị Thanh Thảo | G33: Viện QT&CN | H33: Ngôn ngữ/Giáo dục | I33: Global Communication | J33: 46006 | K33: Tốt | L33: 5000000 | M33: Tiền mặt | N33: 3 | O33: Không ghi nhận | P33: =COUNTIF(02_OUTPUT_ALL!$B:$B,A33) -> 2 | Q33: Tổng hợp đề tài KHCN cấp cơ sở của GV 2021-2025.pdf, mục NĂM 2025 | R33: Nguồn viết 'scarfolding'; chuẩn hóa thành scaffolding trong tên phân tích.
A34: P2025-02 | B34: 2025 | C34: 02-2025/KHCN | D34: Phát triển kiến thức và kỹ năng đổi mới sáng tạo cho sinh viên ngành quản trị kinh doanh Trường Đại học Thành Đô | E34: Cơ sở | F34: Nguyễn Thị Hay | G34: Viện QT&CN | H34: Quản trị kinh doanh/Đổi mới sáng tạo | I34: Digital Services | J34: 46008 | K34: Tốt | M34: Tính giờ NCKH đề tài + bài báo | N34: 1 | O34: Không ghi nhận | P34: =COUNTIF(02_OUTPUT_ALL!$B:$B,A34) -> 2 | Q34: Tổng hợp đề tài KHCN cấp cơ sở của GV 2021-2025.pdf, mục NĂM 2025
A35: P2025-03 | B35: 2025 | C35: 03-2025/KHCN | D35: Nghiên cứu các nhân tố ảnh hưởng đến khả năng tự quyết toán thuế TNCN của người nộp thuế TNCN trên địa bàn thành phố Hà Nội | E35: Cơ sở | F35: Trần Thị Thùy | G35: Viện QT&CN | H35: Kinh tế/Tài chính công/Thuế | I35: Digital Services | J35: 46009 | K35: Tốt | M35: Tính giờ NCKH đề tài + bài báo | N35: 2 | O35: Không ghi nhận | P35: =COUNTIF(02_OUTPUT_ALL!$B:$B,A35) -> 2 | Q35: Tổng hợp đề tài KHCN cấp cơ sở của GV 2021-2025.pdf, mục NĂM 2025
A36: P2025-04 | B36: 2025 | C36: 04-2025/KHCN | D36: Hoàn thiện kỹ năng soạn thảo hợp đồng cho sinh viên Trường Đại học Thành Đô | E36: Cơ sở | F36: Vũ Thị Thu Hà | G36: Viện QT&CN | H36: Luật/Giáo dục kỹ năng | I36: Khác/Chưa phân loại | J36: 46010 | K36: Tốt | M36: Tính giờ NCKH đề tài + bài báo | N36: 3 | O36: Không ghi nhận | P36: =COUNTIF(02_OUTPUT_ALL!$B:$B,A36) -> 1 | Q36: Tổng hợp đề tài KHCN cấp cơ sở của GV 2021-2025.pdf, mục NĂM 2025 | R36: Hồ sơ trích xuất hiện thấy sản phẩm bài báo; cần kiểm tra có báo cáo toàn văn riêng hay không.
A37: P2025-06 | B37: 2025 | C37: 06-2025/KHCN | D37: Nghiên cứu bào chế cồn thuốc xoa bóp hỗ trợ giảm đau nhức xương khớp quy mô phòng thí nghiệm | E37: Cơ sở | F37: Nguyễn Đăng Việt | G37: Viện Y-Dược | H37: Dược/Bào chế | I37: Wellness & Care | J37: 46016 | K37: Tốt | L37: 30000000 | M37: Tiền mặt + tính giờ NCKH | N37: 4 | O37: Có | P37: =COUNTIF(02_OUTPUT_ALL!$B:$B,A37) -> 3 | Q37: Tổng hợp đề tài KHCN cấp cơ sở của GV 2021-2025.pdf, mục NĂM 2025 | R37: Công thức mới, dự kiến đăng ký GPHI.
A38: P2025-07 | B38: 2025 | C38: 07-2025/KHCN | D38: Nghiên cứu bào chế viên ngậm hỗ trợ giảm ho từ Gừng và Húng chanh | E38: Cơ sở | F38: Ngô Thị Thu | G38: Viện Y-Dược | H38: Dược/Bào chế | I38: Wellness & Care | J38: 46016 | K38: Tốt | L38: 30000000 | M38: Tiền mặt + tính giờ NCKH | N38: 4 | O38: Có | P38: =COUNTIF(02_OUTPUT_ALL!$B:$B,A38) -> 4 | Q38: Tổng hợp đề tài KHCN cấp cơ sở của GV 2021-2025.pdf, mục NĂM 2025 | R38: Quy trình mới, dự kiến đăng ký GPHI.
A39: P2025-09 | B39: 2025 | C39: 09-2025/KHCN | D39: Nghiên cứu chiết xuất và đánh giá hoạt tính dược học của lá Quế hoa (Osmanthus fragrans) hướng tới ứng dụng trong thực phẩm chức năng | E39: Cơ sở | F39: Nguyễn Ngọc Linh | G39: Viện Y-Dược | H39: Dược/Hoạt chất tự nhiên | I39: Wellness & Care | J39: 46016 | K39: Xuất sắc | L39: 80000000 | M39: Tiền mặt + tính giờ NCKH; xin thêm 20 triệu | N39: 5 | O39: Có - giai đoạn 2 dự kiến | P39: =COUNTIF(02_OUTPUT_ALL!$B:$B,A39) -> 3 | Q39: Tổng hợp đề tài KHCN cấp cơ sở của GV 2021-2025.pdf, mục NĂM 2025 | R39: Giai đoạn 2 ghi 'Sáng chế' nhưng chưa có bằng chứng đã nộp/cấp.

Sheet 02_OUTPUT_ALL
A1: Output_ID | B1: Project_ID | C1: Năm | D1: Tên đầu ra theo hồ sơ | E1: Loại đầu ra | F1: Số lượng | G1: Đơn vị tính | H1: Trạng thái bằng chứng | I1: Dấu hiệu TSTT? | J1: Hình thức quyền/biện pháp sơ bộ | K1: Ưu tiên quản trị IP | L1: Có dấu hiệu ứng dụng? | M1: Đối chiếu với CSDL công bố | N1: Nguồn | O1: Ghi chú coding | P1: Loại đầu ra chuẩn hóa (v0.8) | Q1: Nhóm mẫu số (v0.8)
A2: O-2021-20-01 | B2: P2021-20 | C2: 2021 | D2: Báo cáo tổng kết đề tài | E2: Báo cáo nghiên cứu | F2: 1 | G2: báo cáo | H2: Đã nghiệm thu | I2: Có | J2: Quyền tác giả | K2: Thấp | L2: Không | M2: Chưa cần | N2: Tổng hợp đề tài KHCN cấp cơ sở của GV 2021-2025.pdf, tr.1 | P2: =IFERROR(VLOOKUP($E2,09B_MAP_LOAI_DAURA!$A$5:$C$18,2,0),"KHÔNG CÓ TRONG TỪ ĐIỂN") -> Báo cáo tổng kết đề tài | Q2: =IFERROR(VLOOKUP($E2,09B_MAP_LOAI_DAURA!$A$5:$C$18,3,0),"KHÔNG CÓ TRONG TỪ ĐIỂN") -> Bắt buộc hành chính
A3: O-2021-22-01 | B3: P2021-22 | C3: 2021 | D3: Báo cáo tổng kết đề tài | E3: Báo cáo nghiên cứu | F3: 1 | G3: báo cáo | H3: Đã nghiệm thu | I3: Có | J3: Quyền tác giả | K3: Thấp | L3: Không | M3: Chưa cần | N3: Tổng hợp đề tài KHCN cấp cơ sở của GV 2021-2025.pdf, tr.1 | P3: =IFERROR(VLOOKUP($E3,09B_MAP_LOAI_DAURA!$A$5:$C$18,2,0),"KHÔNG CÓ TRONG TỪ ĐIỂN") -> Báo cáo tổng kết đề tài | Q3: =IFERROR(VLOOKUP($E3,09B_MAP_LOAI_DAURA!$A$5:$C$18,3,0),"KHÔNG CÓ TRONG TỪ ĐIỂN") -> Bắt buộc hành chính
A4: O-2021-24-01 | B4: P2021-24 | C4: 2021 | D4: Báo cáo tổng kết đề tài | E4: Báo cáo nghiên cứu | F4: 1 | G4: báo cáo | H4: Đã nghiệm thu | I4: Có | J4: Quyền tác giả | K4: Thấp | L4: Không | M4: Chưa cần | N4: Tổng hợp đề tài KHCN cấp cơ sở của GV 2021-2025.pdf, tr.1 | P4: =IFERROR(VLOOKUP($E4,09B_MAP_LOAI_DAURA!$A$5:$C$18,2,0),"KHÔNG CÓ TRONG TỪ ĐIỂN") -> Báo cáo tổng kết đề tài | Q4: =IFERROR(VLOOKUP($E4,09B_MAP_LOAI_DAURA!$A$5:$C$18,3,0),"KHÔNG CÓ TRONG TỪ ĐIỂN") -> Bắt buộc hành chính
A5: O-2021-27-01 | B5: P2021-27 | C5: 2021 | D5: Báo cáo tổng kết đề tài | E5: Báo cáo nghiên cứu | F5: 1 | G5: báo cáo | H5: Đã nghiệm thu | I5: Có | J5: Quyền tác giả | K5: Thấp | L5: Không | M5: Chưa cần | N5: Tổng hợp đề tài KHCN cấp cơ sở của GV 2021-2025.pdf, tr.1 | P5: =IFERROR(VLOOKUP($E5,09B_MAP_LOAI_DAURA!$A$5:$C$18,2,0),"KHÔNG CÓ TRONG TỪ ĐIỂN") -> Báo cáo tổng kết đề tài | Q5: =IFERROR(VLOOKUP($E5,09B_MAP_LOAI_DAURA!$A$5:$C$18,3,0),"KHÔNG CÓ TRONG TỪ ĐIỂN") -> Bắt buộc hành chính
A6: O-2021-27-02 | B6: P2021-27 | C6: 2021 | D6: Bài báo đăng tạp chí quốc tế | E6: Bài báo | F6: 1 | G6: bài | H6: Hồ sơ ghi nhận | I6: Có | J6: Quyền tác giả | K6: Thấp | L6: Không | M6: Cần đối chiếu | N6: Tổng hợp đề tài KHCN cấp cơ sở của GV 2021-2025.pdf, tr.1 | P6: =IFERROR(VLOOKUP($E6,09B_MAP_LOAI_DAURA!$A$5:$C$18,2,0),"KHÔNG CÓ TRONG TỪ ĐIỂN") -> Công bố khoa học | Q6: =IFERROR(VLOOKUP($E6,09B_MAP_LOAI_DAURA!$A$5:$C$18,3,0),"KHÔNG CÓ TRONG TỪ ĐIỂN") -> Công bố
A7: O-2021-27-03 | B7: P2021-27 | C7: 2021 | D7: Bài báo đăng tạp chí trong nước | E7: Bài báo | F7: 1 | G7: bài | H7: Hồ sơ ghi nhận | I7: Có | J7: Quyền tác giả | K7: Thấp | L7: Không | M7: Cần đối chiếu | N7: Tổng hợp đề tài KHCN cấp cơ sở của GV 2021-2025.pdf, tr.1 | P7: =IFERROR(VLOOKUP($E7,09B_MAP_LOAI_DAURA!$A$5:$C$18,2,0),"KHÔNG CÓ TRONG TỪ ĐIỂN") -> Công bố khoa học | Q7: =IFERROR(VLOOKUP($E7,09B_MAP_LOAI_DAURA!$A$5:$C$18,3,0),"KHÔNG CÓ TRONG TỪ ĐIỂN") -> Công bố
A8: O-2021-28-01 | B8: P2021-28 | C8: 2021 | D8: Báo cáo tổng kết đề tài | E8: Báo cáo nghiên cứu | F8: 1 | G8: báo cáo | H8: Đã nghiệm thu | I8: Có | J8: Quyền tác giả | K8: Thấp | L8: Không | M8: Chưa cần | N8: Tổng hợp đề tài KHCN cấp cơ sở của GV 2021-2025.pdf, tr.2 | P8: =IFERROR(VLOOKUP($E8,09B_MAP_LOAI_DAURA!$A$5:$C$18,2,0),"KHÔNG CÓ TRONG TỪ ĐIỂN") -> Báo cáo tổng kết đề tài | Q8: =IFERROR(VLOOKUP($E8,09B_MAP_LOAI_DAURA!$A$5:$C$18,3,0),"KHÔNG CÓ TRONG TỪ ĐIỂN") -> Bắt buộc hành chính
A9: O-2021-28-02 | B9: P2021-28 | C9: 2021 | D9: Bài báo đăng tạp chí quốc tế | E9: Bài báo | F9: 1 | G9: bài | H9: Hồ sơ ghi nhận | I9: Có | J9: Quyền tác giả | K9: Thấp | L9: Không | M9: Cần đối chiếu | N9: Tổng hợp đề tài KHCN cấp cơ sở của GV 2021-2025.pdf, tr.2 | P9: =IFERROR(VLOOKUP($E9,09B_MAP_LOAI_DAURA!$A$5:$C$18,2,0),"KHÔNG CÓ TRONG TỪ ĐIỂN") -> Công bố khoa học | Q9: =IFERROR(VLOOKUP($E9,09B_MAP_LOAI_DAURA!$A$5:$C$18,3,0),"KHÔNG CÓ TRONG TỪ ĐIỂN") -> Công bố
A10: O-2021-28-03 | B10: P2021-28 | C10: 2021 | D10: Bài báo đăng tạp chí trong nước | E10: Bài báo | F10: 2 | G10: bài | H10: Hồ sơ ghi nhận | I10: Có | J10: Quyền tác giả | K10: Thấp | L10: Không | M10: Cần đối chiếu | N10: Tổng hợp đề tài KHCN cấp cơ sở của GV 2021-2025.pdf, tr.2 | P10: =IFERROR(VLOOKUP($E10,09B_MAP_LOAI_DAURA!$A$5:$C$18,2,0),"KHÔNG CÓ TRONG TỪ ĐIỂN") -> Công bố khoa học | Q10: =IFERROR(VLOOKUP($E10,09B_MAP_LOAI_DAURA!$A$5:$C$18,3,0),"KHÔNG CÓ TRONG TỪ ĐIỂN") -> Công bố
A11: O-2021-37-01 | B11: P2021-37 | C11: 2021 | D11: Báo cáo tổng kết đề tài | E11: Báo cáo nghiên cứu | F11: 1 | G11: báo cáo | H11: Đã nghiệm thu | I11: Có | J11: Quyền tác giả | K11: Thấp | L11: Không | M11: Chưa cần | N11: Tổng hợp đề tài KHCN cấp cơ sở của GV 2021-2025.pdf, tr.2 | P11: =IFERROR(VLOOKUP($E11,09B_MAP_LOAI_DAURA!$A$5:$C$18,2,0),"KHÔNG CÓ TRONG TỪ ĐIỂN") -> Báo cáo tổng kết đề tài | Q11: =IFERROR(VLOOKUP($E11,09B_MAP_LOAI_DAURA!$A$5:$C$18,3,0),"KHÔNG CÓ TRONG TỪ ĐIỂN") -> Bắt buộc hành chính
A12: O-2021-37-02 | B12: P2021-37 | C12: 2021 | D12: Bài báo đăng tạp chí trong nước | E12: Bài báo | F12: 1 | G12: bài | H12: Hồ sơ ghi nhận | I12: Có | J12: Quyền tác giả | K12: Thấp | L12: Không | M12: Cần đối chiếu | N12: Tổng hợp đề tài KHCN cấp cơ sở của GV 2021-2025.pdf, tr.2 | P12: =IFERROR(VLOOKUP($E12,09B_MAP_LOAI_DAURA!$A$5:$C$18,2,0),"KHÔNG CÓ TRONG TỪ ĐIỂN") -> Công bố khoa học | Q12: =IFERROR(VLOOKUP($E12,09B_MAP_LOAI_DAURA!$A$5:$C$18,3,0),"KHÔNG CÓ TRONG TỪ ĐIỂN") -> Công bố
A13: O-2022-01-01 | B13: P2022-01 | C13: 2022 | D13: Tạp chí Nghiên cứu khoa học và phát triển thuộc Trường Đại học Thành Đô | E13: Sản phẩm tổ chức/hạ tầng học thuật | F13: 1 | G13: tạp chí | H13: Đã nghiệm thu | I13: Có | J13: Tên/nhãn hiệu, nội dung tạp chí, quy trình vận hành - cần tách quyền | K13: Trung bình | L13: Có | M13: Cần kiểm tra | N13: Tổng hợp đề tài KHCN cấp cơ sở của GV 2021-2025.pdf, tr.2 | P13: =IFERROR(VLOOKUP($E13,09B_MAP_LOAI_DAURA!$A$5:$C$18,2,0),"KHÔNG CÓ TRONG TỪ ĐIỂN") -> Sản phẩm tổ chức/quản trị | Q13: =IFERROR(VLOOKUP($E13,09B_MAP_LOAI_DAURA!$A$5:$C$18,3,0),"KHÔNG CÓ TRONG TỪ ĐIỂN") -> Khác/quản trị
... A91: O-2025-09-03 | B91: P2025-09 | C91: 2025 | D91: Sáng chế - Giai đoạn 2 | E91: Sáng chế dự kiến | F91: 1 | G91: đầu ra dự kiến | H91: Kế hoạch giai đoạn 2; chưa có bằng chứng nộp/cấp | I91: Có | J91: Sáng chế - cần xác minh giai đoạn và hồ sơ đơn | K91: Cao | L91: Dự kiến | M91: Chưa cần | N91: Tổng hợp đề tài KHCN cấp cơ sở của GV 2021-2025.pdf, mục NĂM 2025 | P91: =IFERROR(VLOOKUP($E91,09B_MAP_LOAI_DAURA!$A$5:$C$18,2,0),"KHÔNG CÓ TRONG TỪ ĐIỂN") -> Đối tượng SHCN dự kiến | Q91: =IFERROR(VLOOKUP($E91,09B_MAP_LOAI_DAURA!$A$5:$C$18,3,0),"KHÔNG CÓ TRONG TỪ ĐIỂN") -> Ứng viên TSTT

Sheet 03_IP_PRIORITY_ALL
A1: Priority_IP_ID | B1: Output_ID | C1: Project_ID | D1: Năm | E1: TSTT/đầu ra ưu tiên | F1: Loại đầu ra | G1: Mức ưu tiên | H1: Hình thức quyền/biện pháp sơ bộ | I1: Dấu hiệu ứng dụng | J1: Đã nhận diện chính thức? | K1: Đã sàng lọc IP? | L1: Chủ sở hữu đã xác minh? | M1: Hành động đề xuất | N1: Nguồn | O1: Trạng thái bằng chứng
A2: PRI-001 | B2: O-2022-01-01 | C2: P2022-01 | D2: 2022 | E2: Tạp chí Nghiên cứu khoa học và phát triển thuộc Trường Đại học Thành Đô | F2: Sản phẩm tổ chức/hạ tầng học thuật | G2: Trung bình | H2: Tên/nhãn hiệu, nội dung tạp chí, quy trình vận hành - cần tách quyền | I2: Có | J2: Chưa kiểm tra | K2: Chưa kiểm tra | L2: Chưa kiểm tra | M2: Tách quyền đối với tên/nhãn hiệu, nội dung, quy trình vận hành; xác minh chủ sở hữu và cơ chế khai thác. | N2: Tổng hợp đề tài KHCN cấp cơ sở của GV 2021-2025.pdf, tr.2 | O2: Đã nghiệm thu
A3: PRI-002 | B3: O-2022-02-01 | C3: P2022-02 | D3: 2022 | E3: Quy chế tuyển sinh và đào tạo trình độ thạc sĩ tại Trường Đại học Thành Đô | F3: Văn bản/quy trình quản trị | G3: Trung bình | H3: Quyền tác giả đối với hình thức thể hiện; tri thức/quy trình quản trị | I3: Có | J3: Chưa kiểm tra | K3: Chưa kiểm tra | L3: Chưa kiểm tra | M3: Tài liệu hóa phương pháp/quy trình, xác định chủ sở hữu và bằng chứng sử dụng; xem xét quyền tác giả/know-how và giá trị ứng dụng. | N3: Tổng hợp đề tài KHCN cấp cơ sở của GV 2021-2025.pdf, tr.2 | O3: Đã nghiệm thu
A4: PRI-003 | B4: O-2022-37-02 | C4: P2022-37 | D4: 2022 | E4: Mô hình kiểm tra và sửa chữa hệ thống khởi động điện trên ô tô | F4: Mô hình/prototype | G4: Cao | H4: Giải pháp kỹ thuật/KDCN/know-how - cần sàng lọc | I4: Có | J4: Chưa kiểm tra | K4: Chưa kiểm tra | L4: Chưa kiểm tra | M4: Rà soát tính mới/trình độ sáng tạo/khả năng áp dụng; kiểm tra công bố trước bảo hộ, chủ sở hữu và lựa chọn sáng chế/GPHI/BMKD/KDCN phù hợp. | N4: Tổng hợp đề tài KHCN cấp cơ sở của GV 2021-2025.pdf, tr.3 | O4: Đã nghiệm thu
A5: PRI-004 | B5: O-2022-39-02 | C5: P2022-39 | D5: 2022 | E5: Sản phẩm cầm máu ở dạng màng | F5: Sản phẩm/prototype | G5: Cao | H5: Giải pháp kỹ thuật/sáng chế-GPHI/know-how - cần sàng lọc | I5: Có | J5: Chưa kiểm tra | K5: Chưa kiểm tra | L5: Chưa kiểm tra | M5: Rà soát tính mới/trình độ sáng tạo/khả năng áp dụng; kiểm tra công bố trước bảo hộ, chủ sở hữu và lựa chọn sáng chế/GPHI/BMKD/KDCN phù hợp. | N5: Tổng hợp đề tài KHCN cấp cơ sở của GV 2021-2025.pdf, tr.3 | O5: Đã nghiệm thu
A6: PRI-005 | B6: O-2022-40-02 | C6: P2022-40 | D6: 2022 | E6: Bộ mẫu cây thuốc | F6: Bộ mẫu/collection | G6: Trung bình | H6: Tác phẩm sưu tập/CSDL/học liệu - cần xác định cấu trúc | I6: Có | J6: Chưa kiểm tra | K6: Chưa kiểm tra | L6: Chưa kiểm tra | M6: Xác định cấu trúc sáng tạo, quyền tác giả/CSDL nếu phù hợp; đo mức sử dụng trong đào tạo và chi phí thay thế. | N6: Tổng hợp đề tài KHCN cấp cơ sở của GV 2021-2025.pdf, tr.3 | O6: Đã nghiệm thu
A7: PRI-006 | B7: O-2023-01-03 | C7: P2023-01 | D7: 2023 | E7: Giải pháp bồi dưỡng phương pháp tư duy biện chứng Hồ Chí Minh cho sinh viên Trường Đại học Thành Đô | F7: Giải pháp/phương pháp ứng dụng | G7: Trung bình | H7: Quyền tác giả/know-how phương pháp giáo dục | I7: Có | J7: Chưa kiểm tra | K7: Chưa kiểm tra | L7: Chưa kiểm tra | M7: Tài liệu hóa phương pháp/quy trình, xác định chủ sở hữu và bằng chứng sử dụng; xem xét quyền tác giả/know-how và giá trị ứng dụng. | N7: Tổng hợp đề tài KHCN cấp cơ sở của GV 2021-2025.pdf, tr.4 | O7: Hồ sơ ghi ứng dụng tại Trường
A8: PRI-007 | B8: O-2023-02-03 | C8: P2023-02 | D8: 2023 | E8: Giải pháp nâng cao chất lượng đào tạo học phần Thực hành hướng dẫn du lịch tại Trường Đại học Thành Đô | F8: Giải pháp/phương pháp ứng dụng | G8: Trung bình | H8: Quyền tác giả/know-how phương pháp đào tạo | I8: Có | J8: Chưa kiểm tra | K8: Chưa kiểm tra | L8: Chưa kiểm tra | M8: Tài liệu hóa phương pháp/quy trình, xác định chủ sở hữu và bằng chứng sử dụng; xem xét quyền tác giả/know-how và giá trị ứng dụng. | N8: Tổng hợp đề tài KHCN cấp cơ sở của GV 2021-2025.pdf, tr.4 | O8: Hồ sơ ghi ứng dụng tại Trường
A9: PRI-008 | B9: O-2023-03-03 | C9: P2023-03 | D9: 2023 | E9: Phương pháp giảng dạy giúp sinh viên tự học nhằm nâng cao chất lượng học tập | F9: Giải pháp/phương pháp ứng dụng | G9: Trung bình | H9: Quyền tác giả/know-how phương pháp giáo dục | I9: Có | J9: Chưa kiểm tra | K9: Chưa kiểm tra | L9: Chưa kiểm tra | M9: Tài liệu hóa phương pháp/quy trình, xác định chủ sở hữu và bằng chứng sử dụng; xem xét quyền tác giả/know-how và giá trị ứng dụng. | N9: Tổng hợp đề tài KHCN cấp cơ sở của GV 2021-2025.pdf, tr.5 | O9: Hồ sơ ghi ứng dụng tại Trường
A10: PRI-009 | B10: O-2023-04-03 | C10: P2023-04 | D10: 2023 | E10: Ứng dụng flipped classroom cho sinh viên | F10: Giải pháp/phương pháp ứng dụng | G10: Trung bình | H10: Quyền tác giả/know-how phương pháp giáo dục | I10: Có | J10: Chưa kiểm tra | K10: Chưa kiểm tra | L10: Chưa kiểm tra | M10: Tài liệu hóa phương pháp/quy trình, xác định chủ sở hữu và bằng chứng sử dụng; xem xét quyền tác giả/know-how và giá trị ứng dụng. | N10: Tổng hợp đề tài KHCN cấp cơ sở của GV 2021-2025.pdf, tr.5 | O10: Hồ sơ ghi ứng dụng tại Trường
A11: PRI-010 | B11: O-2023-05-03 | C11: P2023-05 | D11: 2023 | E11: Tài liệu/giải pháp tham khảo xây dựng chính sách và Quy chế hoạt động KHCN | F11: Giải pháp/phương pháp ứng dụng | G11: Trung bình | H11: Quyền tác giả/know-how quản trị | I11: Có | J11: Chưa kiểm tra | K11: Chưa kiểm tra | L11: Chưa kiểm tra | M11: Tài liệu hóa phương pháp/quy trình, xác định chủ sở hữu và bằng chứng sử dụng; xem xét quyền tác giả/know-how và giá trị ứng dụng. | N11: Tổng hợp đề tài KHCN cấp cơ sở của GV 2021-2025.pdf, tr.6 | O11: Hồ sơ ghi khả năng ứng dụng
A12: PRI-011 | B12: O-2023-07-03 | C12: P2023-07 | D12: 2023 | E12: Giải pháp nâng cao nhận thức pháp luật cho sinh viên | F12: Giải pháp/phương pháp ứng dụng | G12: Trung bình | H12: Quyền tác giả/know-how giáo dục pháp luật | I12: Có | J12: Chưa kiểm tra | K12: Chưa kiểm tra | L12: Chưa kiểm tra | M12: Tài liệu hóa phương pháp/quy trình, xác định chủ sở hữu và bằng chứng sử dụng; xem xét quyền tác giả/know-how và giá trị ứng dụng. | N12: Tổng hợp đề tài KHCN cấp cơ sở của GV 2021-2025.pdf, tr.6 | O12: Hồ sơ ghi ứng dụng tại Trường
A13: PRI-012 | B13: O-2023-08-02 | C13: P2023-08 | D13: 2023 | E13: Tinh dầu Citrus grandis (L.) Osbeck 100ml | F13: Sản phẩm/prototype | G13: Cao | H13: Hiện thân của quy trình/know-how; có thể sàng lọc sáng chế-GPHI | I13: Có | J13: Chưa kiểm tra | K13: Chưa kiểm tra | L13: Chưa kiểm tra | M13: Rà soát tính mới/trình độ sáng tạo/khả năng áp dụng; kiểm tra công bố trước bảo hộ, chủ sở hữu và lựa chọn sáng chế/GPHI/BMKD/KDCN phù hợp. | N13: Tổng hợp đề tài KHCN cấp cơ sở của GV 2021-2025.pdf, tr.7 | O13: Đã nghiệm thu
... A27: PRI-026 | B27: O-2025-09-03 | C27: P2025-09 | D27: 2025 | E27: Sáng chế - Giai đoạn 2 | F27: Sáng chế dự kiến | G27: Cao | H27: Sáng chế - cần xác minh giai đoạn và hồ sơ đơn | I27: Dự kiến | J27: Chưa kiểm tra | K27: Chưa kiểm tra | L27: Chưa kiểm tra | M27: Rà soát tính mới/trình độ sáng tạo/khả năng áp dụng; kiểm tra công bố trước bảo hộ, chủ sở hữu và lựa chọn sáng chế/GPHI/BMKD/KDCN phù hợp. | N27: Tổng hợp đề tài KHCN cấp cơ sở của GV 2021-2025.pdf, mục NĂM 2025 | O27: Kế hoạch giai đoạn 2; chưa có bằng chứng nộp/cấp

Sheet 13B_PROTECTION_FULL
A1: Source_ID | B1: Loại hình chuẩn hóa | C1: Tên và nội dung | D1: Số/Ký mã hiệu theo nguồn | E1: Năm | F1: Nơi cấp | G1: Vai trò theo nguồn | H1: Chủ sở hữu | I1: Trạng thái hồ sơ suy ra tối thiểu | J1: Phạm vi đối với nghiên cứu ĐHTĐ | K1: Project_ID liên quan sơ bộ | L1: Mức độ liên kết | M1: Ghi chú phương pháp
A2: SRC-IP-001 | B2: Bản quyền tác giả | C2: Bộ Logo Trường Đại học Thành Đô | D2: 6534/2021/QTG | E2: 2021 | F2: Cục Bản quyền tác giả, Bộ Văn hóa, Thể thao và Du lịch | G2: Tác giả | H2: ĐHTĐ | I2: Đã có số đăng ký | J2: Trực tiếp ĐHTĐ
A3: SRC-IP-002 | B3: Bản quyền tác giả | C3: Bộ Logo UNIGO | D3: 1584/2022/QTG | E3: 2022 | F3: Cục Bản quyền tác giả, Bộ Văn hóa, Thể thao và Du lịch | G3: Tác giả | H3: CTY UNIGO | I3: Đã có số đăng ký | J3: Ngoài phạm vi ĐHTĐ trực tiếp | M3: Giữ trong danh mục nguồn đầy đủ nhưng không đưa vào tử số TSTT trực tiếp của ĐHTĐ.
A4: SRC-IP-003 | B4: Bản quyền tác giả | C4: Bộ Logo Hệ sinh thái giáo dục Trường Đại học Thành Đô | D4: 5790/2023/QTG | E4: 2023 | F4: Cục Bản quyền tác giả, Bộ Văn hóa, Thể thao và Du lịch | G4: Tác giả | H4: ĐHTĐ | I4: Đã có số đăng ký | J4: Trực tiếp ĐHTĐ
A5: SRC-IP-004 | B5: Bản quyền tác giả | C5: Bộ Logo Chương trình Thần đồng Tiếng Việt - Vietnamese LangMaster Kids | D5: 5550/2025/QTG | E5: 2025 | F5: Cục Bản quyền tác giả, Bộ Văn hóa, Thể thao và Du lịch | G5: Tác giả | H5: Trường UNIGO | I5: Đã có số đăng ký | J5: Ngoài phạm vi ĐHTĐ trực tiếp | M5: Giữ để phân biệt tài sản hệ sinh thái với tài sản của ĐHTĐ.
A6: SRC-IP-005 | B6: Nhãn hiệu | C6: Nhãn hiệu chữ "Unigo" | D6: 364106 | E6: 2020 | F6: Cục Sở hữu trí tuệ, Bộ KH&CN | G6: Không ghi | H6: Phan Thị Thanh Thảo | I6: Đã có số văn bằng/ký hiệu | J6: Ngoài phạm vi ĐHTĐ trực tiếp | M6: Năm 2020, ngoài giai đoạn phân tích chính 2021-2025.
A7: SRC-IP-006 | B7: Nhãn hiệu | C7: Thanh do University | D7: 468353 | E7: 2023 | F7: Cục Sở hữu trí tuệ, Bộ KH&CN | G7: Tác giả | H7: ĐHTĐ | I7: Đã có số văn bằng/ký hiệu | J7: Trực tiếp ĐHTĐ
A8: SRC-IP-007 | B8: Nhãn hiệu | C8: Thado Edupark | D8: 545780 | E8: 2025 | F8: Cục Sở hữu trí tuệ, Bộ KH&CN | G8: Tác giả | H8: ĐHTĐ | I8: Đã có số văn bằng/ký hiệu | J8: Trực tiếp ĐHTĐ
A9: SRC-IP-008 | B9: Nhãn hiệu | C9: Double2n | D9: Tiếp nhận đơn | E9: 2023 | F9: Cục Sở hữu trí tuệ, Bộ KH&CN | G9: Đồng tác giả | H9: ĐHTĐ, CTY Thanh Huế | I9: Tiếp nhận đơn; chưa coi là đã được cấp | J9: Trực tiếp ĐHTĐ | M9: Không có số đơn trong danh sách nguồn được cung cấp.
A10: SRC-IP-009 | B10: Nhãn hiệu | C10: Thần Đồng Tiếng Việt | D10: Chờ tiếp nhận | E10: 2025 | F10: Cục Sở hữu trí tuệ, Bộ KH&CN | G10: Không ghi | H10: Phan Thị Thanh Thảo | I10: Chờ tiếp nhận; chưa coi là đã nộp/được cấp | J10: Ngoài phạm vi ĐHTĐ trực tiếp
A11: SRC-IP-010 | B11: Kiểu dáng công nghiệp | C11: Dung dịch vệ sinh phụ nữ | D11: 3-0039693-000 | E11: 2024 | F11: Cục Sở hữu trí tuệ, Bộ KH&CN | G11: Đồng tác giả | H11: ĐHTĐ, CTY Thanh Huế | I11: Đã có số/ký mã hiệu | J11: Trực tiếp ĐHTĐ
A12: SRC-IP-011 | B12: Kiểu dáng công nghiệp | C12: Tinh dầu vỏ bưởi đào | D12: 3-0039694-000 | E12: 2024 | F12: Cục Sở hữu trí tuệ, Bộ KH&CN | G12: Đồng tác giả | H12: ĐHTĐ, CTY Thanh Huế | I12: Đã có số/ký mã hiệu | J12: Trực tiếp ĐHTĐ | K12: P2023-08 | L12: Cao | M12: Tên sản phẩm và bối cảnh hợp tác phù hợp; vẫn cần hồ sơ gốc để khẳng định nguồn từ đề tài.
A13: SRC-IP-012 | B13: Kiểu dáng công nghiệp | C13: Xịt miệng - họng thảo dược | D13: 3-0039902-000 | E13: 2024 | F13: Cục Sở hữu trí tuệ, Bộ KH&CN | G13: Đồng tác giả | H13: ĐHTĐ, CTY Thanh Huế | I13: Đã có số/ký mã hiệu | J13: Trực tiếp ĐHTĐ | M13: Chưa có đầu ra đề tài hiện tại đủ mạnh để liên kết.
A14: SRC-IP-013 | B14: Kiểu dáng công nghiệp | C14: Dầu gội nha đam - bưởi đào | D14: 3-0039695-000 | E14: 2024 | F14: Cục Sở hữu trí tuệ, Bộ KH&CN | G14: Đồng tác giả | H14: ĐHTĐ, CTY Thanh Huế | I14: Đã có số/ký mã hiệu | J14: Trực tiếp ĐHTĐ | M14: Chưa có đầu ra đề tài hiện tại đủ mạnh để liên kết.
A15: SRC-IP-014 | B15: Kiểu dáng công nghiệp | C15: Kem ủ xả tóc - Chiết xuất từ Bưởi - Bơ - Dừa | D15: 3-0039696-000 | E15: 2024 | F15: Cục Sở hữu trí tuệ, Bộ KH&CN | G15: Đồng tác giả | H15: ĐHTĐ, CTY Thanh Huế | I15: Đã có số/ký mã hiệu | J15: Trực tiếp ĐHTĐ | M15: Chưa có đầu ra đề tài hiện tại đủ mạnh để liên kết.
A16: SRC-IP-015 | B16: Sáng chế | C16: Các hợp chất furofuran lignan glucoside và phương pháp chiết các hợp chất này từ lá của cây quế hoa (Osmanthus fragrans) | E16: 2025 | F16: Cục Sở hữu trí tuệ, Bộ KH&CN | G16: Nguyễn Ngọc Linh (ghi tại cột Vai trò) | H16: ĐHTĐ | I16: Có trong danh sách; chưa có số/ký mã hiệu trong nguồn | J16: Trực tiếp ĐHTĐ | K16: P2025-09 | L16: Rất cao | M16: Không suy ra đã nộp hay đã cấp khi chưa có số đơn/văn bằng.
A17: SRC-IP-016 | B17: Sáng chế | C17: Phương pháp chiết tách và phân lập hợp chất Isoembigenin từ cây Piper aduncum L. | E17: 2026 | F17: Cục Sở hữu trí tuệ, Bộ KH&CN | G17: Nguyễn Ngọc Linh (ghi tại cột Vai trò) | H17: ĐHTĐ | I17: Có trong danh sách; chưa có số/ký mã hiệu trong nguồn | J17: Trực tiếp ĐHTĐ | M17: Ngoài giai đoạn 2021-2025; giữ để theo dõi pipeline tiếp theo.

Sheet 08B_KPI_v08
A1: KPI BẢN v0.8 – MỌI CHỈ SỐ GHI RÕ MẪU SỐ VÀ TÍNH BẰNG CÔNG THỨC
A2: Thay thế 08_KPI_ALL (giá trị gõ tay). Tỷ lệ chỉ tính trên mẫu số đã loại đầu ra hành chính bắt buộc.
A4: Mã | B4: Chỉ số | C4: Tử số | D4: Mẫu số | E4: Giá trị | F4: Ghi chú diễn giải
A5: K01 | B5: Tổng số đề tài cấp cơ sở đã kiểm kê | E5: =COUNTA(01_PROJECT_ALL!$A$2:$A$39) -> 38 | F5: Đơn vị phân tích: 1 đề tài.
A6: K02 | B6: Tổng số dòng đầu ra | E6: =COUNTA(02_OUTPUT_ALL!$A$2:$A$91) -> 90 | F6: Dòng đầu ra, không phải số sản phẩm.
A7: K03 | B7: Trong đó: báo cáo tổng kết (bắt buộc hành chính) | E7: =COUNTIF(02_OUTPUT_ALL!$Q$2:$Q$91,"Bắt buộc hành chính") -> 34 | F7: Loại khỏi mọi mẫu số tính tỷ lệ.
A8: K04 | B8: Trong đó: công bố khoa học | E8: =COUNTIF(02_OUTPUT_ALL!$Q$2:$Q$91,"Công bố") -> 30 | F8: Bài báo, kỷ yếu; chưa đối chiếu DOI.
A9: K05 | B9: Trong đó: ứng viên tài sản trí tuệ | E9: =COUNTIF(02_OUTPUT_ALL!$Q$2:$Q$91,"Ứng viên TSTT") -> 24 | F9: Sản phẩm, quy trình, bộ mẫu, học liệu, SHCN dự kiến.
A10: K06 | B10: Trong đó: sản phẩm tổ chức/quản trị | E10: =COUNTIF(02_OUTPUT_ALL!$Q$2:$Q$91,"Khác/quản trị") -> 2 | F10: Không đưa vào phân tích TSTT.
A11: K07 | B11: Mẫu số phân tích TSTT | E11: =E6-E7 -> 56 | F11: K02 trừ K03.
A12: K08 | B12: Tỷ lệ ứng viên TSTT trên mẫu số phân tích | C12: =E9 -> 24 | D12: =E11 -> 56 | E12: =IFERROR(C12/D12,"") -> 0.42857143 | F12: Không gọi là tỷ lệ bảo hộ.
A13: K09 | B13: Số đề tài có ít nhất 1 ứng viên TSTT | E13: =SUMPRODUCT(--(COUNTIFS(02_OUTPUT_ALL!$B$2:$B$91,01_PROJECT_ALL!$A$2:$A$39,02_OUTPUT_ALL!$Q$2:$Q$91,"Ứng viên TSTT")>0)) -> 17 | F13: Tính trên 38 đề tài.
A14: K10 | B14: Tỷ lệ đề tài có ít nhất 1 ứng viên TSTT | C14: =E13 -> 17 | D14: =E5 -> 38 | E14: =IFERROR(C14/D14,"") -> 0.44736842 | F14: Mẫu số gồm cả đề tài thuần lý thuyết.
A15: K11 | B15: Số đề tài hồ sơ ghi có đầu ra ứng dụng | E15: =COUNTIF(01_PROJECT_ALL!$O$2:$O$39,"Có") -> 18 | F15: 19 đề tài ghi 'Không ghi nhận' — không suy ra là không có.
A16: K12 | B16: Tỷ lệ đề tài hồ sơ ghi có đầu ra ứng dụng | C16: =E15 -> 18 | D16: =E5 -> 38 | E16: =IFERROR(C16/D16,"") -> 0.47368421 | F16: Là tỷ lệ ghi nhận trong hồ sơ, không phải tỷ lệ ứng dụng thực tế.
A17: K13 | B17: Đối tượng SHTT ĐHTĐ sở hữu/đồng sở hữu, 2021–2025 | E17: =COUNTIFS(13B_PROTECTION_FULL!$J$2:$J$17,"Trực tiếp ĐHTĐ",13B_PROTECTION_FULL!$E$2:$E$17,"<=2025") -> 11 | F17: Loại tài sản của UNIGO và cá nhân.
A18: K14 | B18: Trong đó đã có số văn bằng/số đăng ký | E18: =COUNTIFS(13B_PROTECTION_FULL!$J$2:$J$17,"Trực tiếp ĐHTĐ",13B_PROTECTION_FULL!$E$2:$E$17,"<=2025",13B_PROTECTION_FULL!$I$2:$I$17,"Đã có*") -> 9 | F18: Loại Double2n (tiếp nhận đơn) và sáng chế chưa có số.
A19: K15 | B19: Tỷ lệ đối tượng đã có số trên portfolio trực tiếp | C19: =E18 -> 9 | D19: =E17 -> 11 | E19: =IFERROR(C19/D19,"") -> 0.81818182 | F19: Chỉ mô tả trạng thái hồ sơ, không phải hiệu quả bảo hộ.
A21: Lưu ý: K05 (ứng viên TSTT theo từ điển v0.8) khác K-cũ 'đầu ra ưu tiên IP' ở 03_IP_PRIORITY_ALL vì hai tiêu chí phân loại khác nhau. Khi viết luận án phải nêu rõ đang dùng định nghĩa nào.

Sheet 24_QC_CHECKS
A1: KIỂM TRA CHẤT LƯỢNG DỮ LIỆU – TỰ ĐỘNG
A2: Mọi dòng phải cho kết quả OK. Chạy lại sau mỗi lần sửa dữ liệu.
A4: Mã | B4: Nội dung kiểm tra | C4: Kỳ vọng | D4: Kết quả | E4: Kết luận
A5: QC01 | B5: Số Project_ID bị trùng trong 01_PROJECT_ALL | C5: 0 | D5: =COUNTA(01_PROJECT_ALL!$A$2:$A$39)-SUMPRODUCT(1/COUNTIF(01_PROJECT_ALL!$A$2:$A$39,01_PROJECT_ALL!$A$2:$A$39)) -> 0 | E5: =IF(D5=C5,"OK","CẦN XỬ LÝ") -> OK
A6: QC02 | B6: Số Output_ID bị trùng trong 02_OUTPUT_ALL | C6: 0 | D6: =COUNTA(02_OUTPUT_ALL!$A$2:$A$91)-SUMPRODUCT(1/COUNTIF(02_OUTPUT_ALL!$A$2:$A$91,02_OUTPUT_ALL!$A$2:$A$91)) -> 0 | E6: =IF(D6=C6,"OK","CẦN XỬ LÝ") -> OK
A7: QC03 | B7: Đầu ra trỏ tới đề tài không tồn tại | C7: 0 | D7: =SUMPRODUCT(--(COUNTIF(01_PROJECT_ALL!$A$2:$A$39,02_OUTPUT_ALL!$B$2:$B$91)=0)) -> 0 | E7: =IF(D7=C7,"OK","CẦN XỬ LÝ") -> OK
A8: QC04 | B8: Dòng ưu tiên IP trỏ tới đầu ra không tồn tại | C8: 0 | D8: =SUMPRODUCT(--(COUNTIF(02_OUTPUT_ALL!$A$2:$A$91,03_IP_PRIORITY_ALL!$B$2:$B$27)=0)) -> 0 | E8: =IF(D8=C8,"OK","CẦN XỬ LÝ") -> OK
A9: QC05 | B9: Loại đầu ra không có trong từ điển 09B | C9: 0 | D9: =SUMPRODUCT(--(COUNTIF(09B_MAP_LOAI_DAURA!$A$5:$A$18,02_OUTPUT_ALL!$E$2:$E$91)=0)) -> 0 | E9: =IF(D9=C9,"OK","CẦN XỬ LÝ") -> OK
A10: QC06 | B10: Tổng 4 nhóm mẫu số phải bằng tổng dòng đầu ra | C10: 0 | D10: =COUNTA(02_OUTPUT_ALL!$A$2:$A$91)-COUNTIF(02_OUTPUT_ALL!$Q$2:$Q$91,"Bắt buộc hành chính")-COUNTIF(02_OUTPUT_ALL!$Q$2:$Q$91,"Công bố")-COUNTIF(02_OUTPUT_ALL!$Q$2:$Q$91,"Ứng viên TSTT")-COUNTIF(02_OUTPUT_ALL!$Q$2:$Q$91,"Khác/quản trị") -> 0 | E10: =IF(D10=C10,"OK","CẦN XỬ LÝ") -> OK
A11: QC07 | B11: Đề tài không có dòng đầu ra nào | C11: 0 | D11: =SUMPRODUCT(--(COUNTIF(02_OUTPUT_ALL!$B$2:$B$91,01_PROJECT_ALL!$A$2:$A$39)=0)) -> 0 | E11: =IF(D11=C11,"OK","CẦN XỬ LÝ") -> OK
A12: QC08 | B12: Đối tượng SHTT thiếu cả số văn bằng lẫn ghi chú trạng thái | C12: 0 | D12: =SUMPRODUCT(--((13B_PROTECTION_FULL!$D$2:$D$17="")*(13B_PROTECTION_FULL!$I$2:$I$17=""))) -> 0 | E12: =IF(D12=C12,"OK","CẦN XỬ LÝ") -> OK

Sheet 09B_MAP_LOAI_DAURA
A1: BẢNG ÁNH XẠ LOẠI ĐẦU RA – CHUẨN HÓA v0.8
A2: Giữ nguyên giá trị gốc trong 02_OUTPUT_ALL cột E; cột P và Q là giá trị chuẩn hóa tra theo bảng này.
A4: Giá trị gốc trong hồ sơ | B4: Loại đầu ra chuẩn hóa (8 nhóm) | C4: Nhóm mẫu số
A5: Báo cáo nghiên cứu | B5: Báo cáo tổng kết đề tài | C5: Bắt buộc hành chính
A6: Bài báo | B6: Công bố khoa học | C6: Công bố
A7: Công bố khoa học | B7: Công bố khoa học | C7: Công bố
A8: Bài hội thảo | B8: Công bố khoa học | C8: Công bố
A9: Sản phẩm/prototype | B9: Sản phẩm/mô hình/prototype | C9: Ứng viên TSTT
A10: Mô hình/prototype | B10: Sản phẩm/mô hình/prototype | C10: Ứng viên TSTT
A11: Quy trình/công thức | B11: Quy trình/giải pháp/công thức | C11: Ứng viên TSTT
A12: Giải pháp/phương pháp ứng dụng | B12: Quy trình/giải pháp/công thức | C12: Ứng viên TSTT
A13: Bộ mẫu/collection | B13: Bộ mẫu/CSDL/học liệu | C13: Ứng viên TSTT
A14: Cẩm nang/học liệu | B14: Bộ mẫu/CSDL/học liệu | C14: Ứng viên TSTT
A15: Sáng chế dự kiến | B15: Đối tượng SHCN dự kiến | C15: Ứng viên TSTT
... A18: Văn bản/quy trình quản trị | B18: Sản phẩm tổ chức/quản trị | C18: Khác/quản trị

Sheet 06_LEGAL_GAP
A1: Gap_ID | B1: Khâu quản trị | C1: Yêu cầu/quy định nội bộ | D1: Nguồn quy định | E1: Bằng chứng thực tế cần thu | F1: Bằng chứng hiện có | G1: Mức tuân thủ (0-2) | H1: Mức độ rủi ro | I1: Khoảng cách sơ bộ | J1: Dữ liệu cần xin thêm | K1: Khuyến nghị kiểm tra
A2: G01 | B2: Nhận diện và kiểm kê TSTT | C2: Quy chế quản trị TSTT bao quát tạo lập, xác lập, bảo vệ và khai thác thương mại TSTT; cần có cơ chế nhận diện TSTT phát sinh. | D2: QC SHTT ĐHTĐ.docx | E2: Sổ/CSDL TSTT, phiếu khai báo, hồ sơ nhận diện | F2: Người dùng xác nhận hiện không có phiếu khai báo/biên bản nhận diện hoặc sổ/CSDL tương đương. | H2: Cao | I2: Khoảng trống về tài liệu hóa và khả năng truy vết khâu nhận diện; chưa đủ căn cứ để kết luận hoạt động nhận diện không diễn ra. | J2: CSDL/sổ đăng ký TSTT | K2: Kiểm tra có danh mục TSTT tập trung và thời điểm ghi nhận.
A3: G02 | B3: Xác định chủ sở hữu | C3: Quy chế KHCN 2021 quy định quyền SHTT đối với kết quả nghiên cứu đề tài thuộc Trường; tác giả hưởng quyền tác giả và các bên thỏa thuận quyền nộp đơn/phân chia lợi ích. | D3: QĐ 213/QĐ-ĐHTĐ 2021 | E3: Hợp đồng/thuyết minh/biên bản xác định chủ sở hữu từng đề tài | F3: Có quy định chung; chưa đối chiếu hồ sơ từng dự án | H3: Cao | I3: Có nguy cơ gap giữa quy định chung và hồ sơ cụ thể | J3: Hợp đồng đề tài; thỏa thuận đồng sở hữu | K3: Lấy mẫu 10–20 đề tài có sản phẩm ứng dụng để audit.
A4: G03 | B4: Bảo mật trước công bố | C4: Quy chế KHCN 2021 yêu cầu bảo mật kết quả; phổ biến/sử dụng phải có thỏa thuận bằng văn bản trong trường hợp thuộc phạm vi điều chỉnh. | D4: QĐ 213/QĐ-ĐHTĐ 2021 | E4: Ngày công bố bài báo vs ngày sàng lọc/nộp đơn | F4: Có các đề tài vừa có bài báo vừa dự kiến đăng ký GPHI | H4: Cao | I4: Có rủi ro công bố trước khi hoàn tất sàng lọc IP | J4: Ngày accepted/published và ngày nộp đơn | K4: Ưu tiên audit P2025-06 và P2025-07.
A5: G04 | B5: Đăng ký xác lập quyền | C5: Cần thống nhất quyền nộp đơn và thực hiện đăng ký khi có tài sản đủ điều kiện. | D5: QĐ 213/QĐ-ĐHTĐ 2021; QC SHTT | E5: Số đơn, ngày nộp, trạng thái, chủ đơn | F5: Có danh sách đơn/văn bằng tổng hợp, nhưng người dùng xác nhận không có hồ sơ sàng lọc/tra cứu khả năng bảo hộ. | H5: Cao | I5: Có đầu ra được bảo hộ/đang xử lý nhưng thiếu hồ sơ giải thích quyết định chọn đối tượng, loại quyền và thời điểm nộp. | J5: Danh sách đơn SHTT của Trường | K5: Đối chiếu từng IP_ID với dữ liệu/hồ sơ trường.
A6: G05 | B6: Ứng dụng/chuyển giao | C6: Quy chế KHCN quy định chuyển giao và phân chia lợi ích; sản phẩm hợp tác DN phải tuân thủ hợp đồng và quyền SHTT. | D6: QĐ 213/QĐ-ĐHTĐ 2021 | E6: Hợp đồng chuyển giao, biên bản bàn giao, đối tác, doanh thu | F6: Người dùng xác nhận không có hợp đồng chuyển giao/cấp phép/biên bản thương mại hóa trong bộ hồ sơ hiện có. | H6: Cao | I6: Không thể xác nhận giao dịch thương mại chỉ từ mô tả 'chuyển giao/ứng dụng' trong hồ sơ nghiệm thu. | J6: Hợp đồng/biên bản/doanh thu | K6: Phân biệt chuyển giao nội bộ, cấp phép, bán sản phẩm, CGCN ra ngoài.
A7: G06 | B7: Phân chia lợi ích | C7: Quy chế KHCN 2021 có tỷ lệ phân chia lợi nhuận cho một số trường hợp thương mại hóa/chuyển giao. | D7: QĐ 213/QĐ-ĐHTĐ 2021 | E7: Chứng từ phân chia lợi ích thực tế | F7: Chưa có trong bộ dữ liệu | H7: Trung bình | I7: Chưa đánh giá | J7: Hồ sơ tài chính, quyết định chi | K7: Kiểm tra đã từng kích hoạt cơ chế này chưa.
A8: G07 | B8: Định giá TSTT | C8: Đề cương nghiên cứu đặt vấn đề hiệu quả quản lý/bảo hộ/thương mại hóa; dữ liệu hiện chưa cho thấy quy trình định giá. | D8: Đề xuất KHCN 2026 + hồ sơ nội bộ cần kiểm chứng | E8: Hồ sơ thẩm định/định giá, tiêu chí lựa chọn | F8: Chưa có trong bộ dữ liệu | H8: Trung bình | I8: Có thể là khoảng trống quản trị | J8: Biên bản định giá/thẩm định | K8: Không kết luận 'không có' trước khi kiểm tra hồ sơ tài chính/pháp chế.
A9: G08 | B9: Theo dõi vòng đời quyền | C9: Quản trị TSTT cần theo dõi tình trạng đơn/văn bằng và khai thác. | D9: QC SHTT ĐHTĐ.docx | E9: Ngày nộp/cấp/gia hạn/hết hạn/chi phí | F9: Bảng thống kê văn bằng hiện mới là ảnh/danh sách rời | H9: Trung bình | I9: Dữ liệu phân tán | J9: Sổ theo dõi văn bằng | K9: Chuẩn hóa thành PROTECTION table.
A10: G09 | B10: Liên kết ĐH-DN | C10: Quy chế KHCN khuyến khích hợp tác nghiên cứu, chuyển giao công nghệ với doanh nghiệp. | D10: QĐ 213/QĐ-ĐHTĐ 2021 | E10: Hợp đồng hợp tác, contribution, điều khoản IP | F10: Một số đề tài có yếu tố hợp tác ĐH-DN | H10: Trung bình | I10: Chưa biết điều khoản IP được xác lập từ đầu hay sau nghiên cứu | J10: Hợp đồng hợp tác | K10: Audit điều khoản background IP/foreground IP.
A11: G10 | B11: Ứng dụng nội bộ | C11: Kết quả KHCN có thể phục vụ đào tạo, nghiên cứu và phát triển Nhà trường. | D11: QĐ 213/QĐ-ĐHTĐ 2021 | E11: Minh chứng sử dụng trong môn học/phòng thực hành/quản trị | F11: Một số sản phẩm có mục tiêu đào tạo rõ (bộ mẫu, panel) | H11: Trung bình | I11: Chưa có chỉ số đo mức sử dụng | J11: Kế hoạch môn học, biên bản bàn giao, số lượt sử dụng | K11: Tách 'có sản phẩm' khỏi 'được sử dụng thực tế'.
A12: G11 | B12: Cơ sở dữ liệu và số hóa | C12: Đề cương nhấn mạnh số hóa quản trị TSTT; QC TSTT tạo nền cho quản lý tập trung. | D12: Đề xuất KHCN 2026; QC SHTT | E12: Phần mềm/CSDL/IP disclosure workflow | F12: Chưa có bằng chứng trong bộ dữ liệu | H12: Trung bình | I12: Chưa đánh giá | J12: Quy trình phần mềm/phân quyền | K12: Khảo sát Phòng KHCN về hệ thống đang dùng.
A13: G12 | B13: Động lực cá nhân | C13: Quy chế có cơ chế quyền lợi/khen thưởng; hiệu quả phụ thuộc nhận thức và động lực giảng viên. | D13: QĐ 213/QĐ-ĐHTĐ 2021; đề cương 2026 | E13: Khảo sát TPB/động lực, phỏng vấn | F13: Chưa có dữ liệu khảo sát | H13: Trung bình | I13: Chưa đánh giá | J13: Khảo sát giảng viên/chuyên gia | K13: Đo thái độ, chuẩn chủ quan, perceived control, incentive fairness.

Sheet 07_CODEBOOK
A1: Dataset | B1: Biến | C1: Nhãn/ý nghĩa | D1: Kiểu | E1: Mã hóa/giá trị hợp lệ | F1: Bắt buộc? | G1: Nguồn dự kiến | H1: Ghi chú coding
A2: PROJECT | B2: Project_ID | C2: Mã duy nhất đề tài | D2: Text | E2: PYYYY-XX | F2: Có | G2: Hồ sơ đề tài | H2: Không đổi sau khi gán
A3: PROJECT | B3: Năm | C3: Năm nghiệm thu/ghi nhận | D3: Integer | E3: 2021–2025 | F3: Có | G3: Hồ sơ đề tài | H3: Ưu tiên năm nghiệm thu
A4: PROJECT | B4: Mã đề tài | C4: Mã quản lý nội bộ | D4: Text | E4: Theo quyết định | F4: Có | G4: Hồ sơ đề tài
A5: PROJECT | B5: Tên đề tài | C5: Tên đầy đủ | D5: Text | E5: Nguyên văn | F5: Có | G5: Hồ sơ đề tài | H5: Không tự chuẩn hóa làm mất nghĩa
A6: PROJECT | B6: Cấp đề tài | C6: Cấp quản lý | D6: Category | E6: Cơ sở/Quốc gia/Bộ/Tỉnh/Khác | F6: Có | G6: Hồ sơ
A7: PROJECT | B7: Chủ nhiệm | C7: Chủ nhiệm đề tài | D7: Text | F7: Có | G7: Hồ sơ
A8: PROJECT | B8: Đơn vị chủ trì | C8: Khoa/viện/phòng | D8: Category | E8: Chuẩn hóa tên đơn vị | F8: Có | G8: Hồ sơ | H8: Giữ thêm tên gốc nếu đổi tổ chức
A9: PROJECT | B9: Nhóm ngành chuẩn hóa | C9: Nhóm chuyên môn | D9: Category | E9: Dược/Kỹ thuật/Kinh tế/CNTT/NN-DL/... | F9: Không | G9: Suy từ đơn vị+nội dung | H9: Có bảng mapping
A10: PROJECT | B10: Strategic_Cluster | C10: Trụ cột chiến lược 2030 | D10: Category | E10: Smart Mobility/Digital Services/Global Communication/Wellness & Care/Khác | F10: Không | G10: Khung chiến lược
A11: PROJECT | B11: Ngày nghiệm thu | C11: Ngày nghiệm thu | D11: Date | E11: dd/mm/yyyy | F11: Không | G11: QĐ/biên bản
A12: PROJECT | B12: Xếp loại | C12: Kết quả nghiệm thu | D12: Category | E12: Đạt/Tốt/Xuất sắc/Khác | F12: Không | G12: Hồ sơ
A13: PROJECT | B13: Kinh phí_VND | C13: Kinh phí thực hiện | D13: Number | E13: VND | F13: Không | G13: Hồ sơ | H13: Tách phần quy đổi giờ nếu cần
A14: PROJECT | B14: Số thành viên | C14: Quy mô nhóm | D14: Integer | E14: >=1 | F14: Không | G14: Hồ sơ | H14: Tính chủ nhiệm + thành viên
A15: PROJECT | B15: Có DN tham gia? | C15: Có doanh nghiệp trong nhóm/hợp tác | D15: Category | E15: Có/Không/Chưa xác minh | F15: Không | G15: Hồ sơ/hợp đồng | H15: Không suy từ tên đề tài
A16: PROJECT | B16: Có SV tham gia? | C16: Có người học tham gia | D16: Category | E16: Có/Không/Chưa xác minh | F16: Không | G16: Hồ sơ
A17: PROJECT | B17: Số đầu ra | C17: Tổng output liên kết | D17: Formula | E17: COUNTIF OUTPUT | F17: Tự động | G17: Dataset
A18: OUTPUT | B18: Output_ID | C18: Mã đầu ra | D18: Text | E18: OYYYY-Project-Seq | F18: Có | G18: Dataset
A19: OUTPUT | B19: Project_ID | C19: Khóa liên kết đề tài | D19: Text | E19: Phải tồn tại ở PROJECT | F19: Có | G19: Dataset
A20: OUTPUT | B20: Tên đầu ra | C20: Tên sản phẩm/đầu ra | D20: Text | E20: Nguyên văn tối đa | F20: Có | G20: Sản phẩm nghiệm thu
A21: OUTPUT | B21: Loại đầu ra | C21: Loại vật mang kết quả | D21: Category | E21: Báo cáo/Bài báo/Sách-GT/CSDL/Phần mềm/Quy trình/Sản phẩm/Mô hình/Thiết kế/Nhãn hiệu/Khác | F21: Có | G21: Coding
A22: OUTPUT | B22: Số lượng | C22: Số lượng đầu ra | D22: Number | E22: >=0 | F22: Không | G22: Hồ sơ
A23: OUTPUT | B23: Đã công bố? | C23: Trạng thái công bố | D23: Category | E23: Có/Có nội bộ/Chưa/Chưa xác minh | F23: Không | G23: Hồ sơ
A24: OUTPUT | B24: Dấu hiệu TSTT? | C24: Có khả năng là TSTT | D24: Category | E24: Có/Không/Chưa xác minh | F24: Có | G24: Coding | H24: Không đồng nghĩa đủ điều kiện bảo hộ độc quyền
A25: OUTPUT | B25: Nhóm TSTT sơ bộ | C25: Phân nhóm sơ bộ | D25: Category | E25: Học thuật/Công nghệ/Số/Thương hiệu/Khác | F25: Không | G25: Coding
A26: OUTPUT | B26: Khả năng tạo giá trị | C26: Dạng giá trị tiềm năng | D26: Multi-category | E26: Khoa học/Đào tạo/Công nghệ/Kinh tế/Chiến lược/Xã hội | F26: Không | G26: Coding
A27: OUTPUT | B27: Bằng chứng nguồn | C27: Nguồn chứng minh | D27: Text | E27: Tên file + trang/dòng | F27: Có | G27: File nội bộ
A28: OUTPUT | B28: Mức tin cậy | C28: Độ chắc chắn coding | D28: Category | E28: Cao/Trung bình/Thấp | F28: Có | G28: Coder
A29: IP_ASSET | B29: IP_ID | C29: Mã TSTT/cụm TSTT | D29: Text | E29: IPYYYY-XX-A | F29: Có | G29: Dataset
A30: IP_ASSET | B30: Tên TSTT/cụm TSTT | C30: Đối tượng quản trị | D30: Text | F30: Có | G30: Output/hồ sơ
A31: IP_ASSET | B31: Nhóm TSTT | C31: Nhóm bản chất | D31: Category | E31: Học thuật/Công nghệ/Số/Thương hiệu/Dữ liệu/Khác | F31: Có | G31: Coding
A32: IP_ASSET | B32: Hình thức quyền dự kiến | C32: Quyền có thể áp dụng | D32: Category | E32: QTG/Sáng chế/GPHI/KDCN/Nhãn hiệu/BMKD/CSDL/Khác/Chưa xác minh | F32: Không | G32: Sàng lọc IP | H32: Không tự kết luận nếu thiếu tra cứu
A33: IP_ASSET | B33: Chủ thể sáng tạo rõ? | C33: Xác định tác giả/người tạo | D33: Category | E33: Có/Không/Chưa xác minh | F33: Có | G33: Hồ sơ
A34: IP_ASSET | B34: Chủ sở hữu rõ? | C34: Có bằng chứng sở hữu cụ thể | D34: Category | E34: Có/Không/Chưa xác minh | F34: Có | G34: Hợp đồng/quy chế
A35: IP_ASSET | B35: Trường sở hữu/đồng sở hữu? | C35: Vị thế của Trường | D35: Category | E35: Có/Đồng sở hữu/Không/Chưa xác minh | F35: Không | G35: Hồ sơ
A36: IP_ASSET | B36: Nguồn lực trường? | C36: Có sử dụng nguồn lực Trường | D36: Category | E36: Có/Không/Một phần/Chưa xác minh | F36: Không | G36: Hồ sơ
